Workbook

Sheet 00 Read me
A1: HML Video Lessons · Content below the video · Lessons 1 to 10
A2: Curated by Battumur.D. Everything a student sees under each lesson video. The developer decides how to build it; this file is the content and the rules.
A4: WHAT SITS UNDER EACH VIDEO
A5: 1 · Тэмдэглэл (Notes) | B5: A one-screen bilingual summary of the video: rule, examples, the Mongolian-speaker mistake, what to remember. Sheet 02. Shown as plain reading content, English with Mongolian under each line.
A6: 2 · Дасгал (Practice) | B6: 18 questions per lesson in three rounds: 1 Recognise (6), 2 Build (8), 3 Fix it (4). Sheet 03, Block = Practice. Shown in round order.
A7: 3 · Шалгалт (Check) | B7: 10 questions drawn from a bank of 20 per lesson. Sheet 03, Block = Check bank.
A8: ACROSS LESSONS
A9: Бүлгийн шалгалт (Unit test) | B9: Unit test 1 after Lesson 5 (covers 1 to 5). Unit test 2 after Lesson 10 (covers 6 to 10, plus one question each from 1 to 5). 20 questions each, never used anywhere else. Sheet 03, Block = Unit test 1 / Unit test 2.
A10: Алдаагаа давт (Mistake review) | B10: A personal list of questions the student got wrong anywhere. No new content: it reuses sheet 03.
A11: RULES · PRACTICE
A12: Attempts | B12: Unlimited. A wrong answer can be tried again straight away.
A13: Feedback | B13: Right: show "Зөв!" and the Mongolian translation. Wrong: show the Mongolian feedback for that question and a Watch again link (see below). Then let them try again.
A14: Translation (MN) | B14: Show only after the student answers, never before. It is there so a beginner understands what the sentence means. Mongolian тэр does not give away he, she or it, so it is safe on pronoun questions.
A15: Hint (MN) | B15: Shown with the question, before answering. Used where a picture or a near/far situation is needed.
A16: Image needed | B16: A few questions in Lesson 10 need a small box-and-ball picture. The description is in the Image column; the slide 2 diagrams in the lesson deck can be reused.
A17: RULES · CHECK
A18: Selection | B18: Draw 10 at random from the lesson's 20 Check bank questions, with at least one question from each skill tag that appears in that bank.
A19: Pass mark | B19: 8 out of 10. Passing marks the lesson complete.
A20: Retake | B20: Unlimited. Each retake draws a new set of 10.
A21: During the check | B21: No feedback until the end. Then show the score and, for each wrong answer, the feedback and Watch again link.
A22: Never lock | B22: Passing marks the lesson complete; failing never blocks the next lesson. The course recommends, it does not lock.
A23: RULES · UNIT TESTS
A24: Format | B24: All 20 questions, order shuffled. No feedback until the end.
A25: Pass mark | B25: 14 out of 20.
A26: Result screen | B26: Score, then the two lessons with the most mistakes, each with a link to its video and practice.
A27: RULES · MISTAKE REVIEW
A28: What goes in | B28: Every question answered wrong in Practice, Check or a Unit test.
A29: When it comes back | B29: 1 day, 3 days and 7 days after the mistake.
A30: When it leaves | B30: After it is answered correctly twice in a row.
A31: Session | B31: Up to 10 questions. Where possible show a different question with the same skill tag first, so students learn the rule rather than memorise one answer.
A32: RULES · WATCH AGAIN LINK
A33: How it works | B33: Every question has a slide number. When each video is recorded, the teacher submits a timestamp log (slide number → start time). The link jumps the video to that time. Text: "Видеог {mm:ss}-аас дахин үзэх" (Watch the video again from {mm:ss}).
A34: RULES · ANSWERING
A35: Tap only | B35: No typing at A1. Every question type is answered by tapping, so students are never marked wrong for a typo.
A36: Shuffle | B36: Shuffle the options of MCQ, CHOOSE, GAP, ORDER, MATCH and SORT every time. The Answer column stores the text, never a position.
A37: Also accept | B37: Some ORDER questions have a second correct order. Accept the Answer or anything in Also accept.
A38: FILE CONTENTS
A39: 01 Lessons | B39: The 10 lessons, codes, titles and question counts.
A40: 02 Notes | B40: The Notes block for every lesson.
A41: 03 Questions | B41: Every question: practice, check banks, unit tests. One row per question, ready to import.
...

Sheet 01 Lessons
A1: Lesson | B1: Code | C1: Title (EN) | D1: Title (MN) | E1: Video slides | F1: Practice | G1: Check bank | H1: Unit test items | I1: Notes lines
A2: 1 | B2: GR-003 | C2: Personal pronouns | D2: Хувийн төлөөний үг | E2: 10 | F2: =COUNTIFS('03 Questions'!$B$2:$B$421,A2,'03 Questions'!$D$2:$D$421,"Practice") -> 18 | G2: =COUNTIFS('03 Questions'!$B$2:$B$421,A2,'03 Questions'!$D$2:$D$421,"Check bank") -> 20 | H2: =COUNTIFS('03 Questions'!$B$2:$B$421,A2,'03 Questions'!$D$2:$D$421,"Unit test*") -> 5 | I2: =COUNTIF('02 Notes'!$A:$A,A2) -> 13
A3: 2 | B3: GR-004 | C3: to be: positive | D3: To be үйл үг: эерэг хэлбэр | E3: 10 | F3: =COUNTIFS('03 Questions'!$B$2:$B$421,A3,'03 Questions'!$D$2:$D$421,"Practice") -> 18 | G3: =COUNTIFS('03 Questions'!$B$2:$B$421,A3,'03 Questions'!$D$2:$D$421,"Check bank") -> 20 | H3: =COUNTIFS('03 Questions'!$B$2:$B$421,A3,'03 Questions'!$D$2:$D$421,"Unit test*") -> 5 | I3: =COUNTIF('02 Notes'!$A:$A,A3) -> 13
A4: 3 | B4: GR-005 | C4: to be: negative and questions | D4: To be: үгүйсгэх ба асуух хэлбэр | E4: 10 | F4: =COUNTIFS('03 Questions'!$B$2:$B$421,A4,'03 Questions'!$D$2:$D$421,"Practice") -> 18 | G4: =COUNTIFS('03 Questions'!$B$2:$B$421,A4,'03 Questions'!$D$2:$D$421,"Check bank") -> 20 | H4: =COUNTIFS('03 Questions'!$B$2:$B$421,A4,'03 Questions'!$D$2:$D$421,"Unit test*") -> 5 | I4: =COUNTIF('02 Notes'!$A:$A,A4) -> 13
A5: 4 | B5: GR-001 | C5: Nouns: singular and plural | D5: Нэр үг: ганц ба олон тоо | E5: 10 | F5: =COUNTIFS('03 Questions'!$B$2:$B$421,A5,'03 Questions'!$D$2:$D$421,"Practice") -> 18 | G5: =COUNTIFS('03 Questions'!$B$2:$B$421,A5,'03 Questions'!$D$2:$D$421,"Check bank") -> 20 | H5: =COUNTIFS('03 Questions'!$B$2:$B$421,A5,'03 Questions'!$D$2:$D$421,"Unit test*") -> 5 | I5: =COUNTIF('02 Notes'!$A:$A,A5) -> 13
A6: 5 | B6: GR-002 | C6: a and an | D6: A ба an | E6: 11 | F6: =COUNTIFS('03 Questions'!$B$2:$B$421,A6,'03 Questions'!$D$2:$D$421,"Practice") -> 18 | G6: =COUNTIFS('03 Questions'!$B$2:$B$421,A6,'03 Questions'!$D$2:$D$421,"Check bank") -> 20 | H6: =COUNTIFS('03 Questions'!$B$2:$B$421,A6,'03 Questions'!$D$2:$D$421,"Unit test*") -> 5 | I6: =COUNTIF('02 Notes'!$A:$A,A6) -> 13
A7: 6 | B7: GR-006 | C7: this, that, these, those | D7: Заах төлөөний үг | E7: 10 | F7: =COUNTIFS('03 Questions'!$B$2:$B$421,A7,'03 Questions'!$D$2:$D$421,"Practice") -> 18 | G7: =COUNTIFS('03 Questions'!$B$2:$B$421,A7,'03 Questions'!$D$2:$D$421,"Check bank") -> 20 | H7: =COUNTIFS('03 Questions'!$B$2:$B$421,A7,'03 Questions'!$D$2:$D$421,"Unit test*") -> 3 | I7: =COUNTIF('02 Notes'!$A:$A,A7) -> 13
A8: 7 | B8: GR-008 | C8: Possessive adjectives | D8: Хамаатуулах төлөөний үг | E8: 10 | F8: =COUNTIFS('03 Questions'!$B$2:$B$421,A8,'03 Questions'!$D$2:$D$421,"Practice") -> 18 | G8: =COUNTIFS('03 Questions'!$B$2:$B$421,A8,'03 Questions'!$D$2:$D$421,"Check bank") -> 20 | H8: =COUNTIFS('03 Questions'!$B$2:$B$421,A8,'03 Questions'!$D$2:$D$421,"Unit test*") -> 3 | I8: =COUNTIF('02 Notes'!$A:$A,A8) -> 12
A9: 8 | B9: GR-007 | C9: have got | D9: Have got бүтэц | E9: 10 | F9: =COUNTIFS('03 Questions'!$B$2:$B$421,A9,'03 Questions'!$D$2:$D$421,"Practice") -> 18 | G9: =COUNTIFS('03 Questions'!$B$2:$B$421,A9,'03 Questions'!$D$2:$D$421,"Check bank") -> 20 | H9: =COUNTIFS('03 Questions'!$B$2:$B$421,A9,'03 Questions'!$D$2:$D$421,"Unit test*") -> 3 | I9: =COUNTIF('02 Notes'!$A:$A,A9) -> 13
A10: 9 | B10: GR-015 | C10: there is and there are | D10: There is / there are бүтэц | E10: 10 | F10: =COUNTIFS('03 Questions'!$B$2:$B$421,A10,'03 Questions'!$D$2:$D$421,"Practice") -> 18 | G10: =COUNTIFS('03 Questions'!$B$2:$B$421,A10,'03 Questions'!$D$2:$D$421,"Check bank") -> 20 | H10: =COUNTIFS('03 Questions'!$B$2:$B$421,A10,'03 Questions'!$D$2:$D$421,"Unit test*") -> 3 | I10: =COUNTIF('02 Notes'!$A:$A,A10) -> 13
A11: 10 | B11: GR-016 | C11: Prepositions of place | D11: Байршлын угтвар үг | E11: 10 | F11: =COUNTIFS('03 Questions'!$B$2:$B$421,A11,'03 Questions'!$D$2:$D$421,"Practice") -> 18 | G11: =COUNTIFS('03 Questions'!$B$2:$B$421,A11,'03 Questions'!$D$2:$D$421,"Check bank") -> 20 | H11: =COUNTIFS('03 Questions'!$B$2:$B$421,A11,'03 Questions'!$D$2:$D$421,"Unit test*") -> 3 | I11: =COUNTIF('02 Notes'!$A:$A,A11) -> 13
A12: Total | F12: =SUM(F2:F11) -> 180 | G12: =SUM(G2:G11) -> 200 | H12: =SUM(H2:H11) -> 40 | I12: =SUM(I2:I11) -> 129

Sheet 02 Notes
A1: Lesson | B1: Code | C1: Order | D1: Section | E1: English | F1: Монгол
A2: 1 | B2: GR-003 | C2: 0 | D2: Title | E2: Personal pronouns | F2: Хувийн төлөөний үг
A3: 1 | B3: GR-003 | C3: 1 | D3: Rule | E3: A pronoun replaces a word you already said. | F3: Төлөөний үг өмнө хэлсэн үгийг орлодог.
A4: 1 | B4: GR-003 | C4: 2 | D4: Rule | E4: The seven pronouns: I, you, he, she, it, we, they. | F4: Долоон төлөөний үг: I (би), you (чи, та, та нар), he, she, it (тэр), we (бид), they (тэд).
A5: 1 | B5: GR-003 | C5: 3 | D5: Rule | E5: тэр is three English words: he for a man, she for a woman, it for a thing. | F5: Монголын "тэр" англиар гурван үг: he (эрэгтэй), she (эмэгтэй), it (юм).
A6: 1 | B6: GR-003 | C6: 4 | D6: Example | E6: Bat is a student. He is 12. | F6: Бат сурагч. Тэр 12 настай.
A7: 1 | B7: GR-003 | C7: 5 | D7: Example | E7: Saraa is my sister. She is a doctor. | F7: Сараа миний эгч. Тэр эмч.
A8: 1 | B8: GR-003 | C8: 6 | D8: Example | E8: This is my phone. It is new. | F8: Энэ миний утас. Тэр шинэ.
A9: 1 | B9: GR-003 | C9: 7 | D9: Example | E9: Bat and I are friends. We are in the same class. | F9: Бат бид хоёр найзууд. Бид нэг ангийнх.
A10: 1 | B10: GR-003 | C10: 8 | D10: Watch out | E10: My mother is a teacher. He is kind. → She is kind. | F10: Ээж эмэгтэй тул she.
A11: 1 | B11: GR-003 | C11: 9 | D11: Watch out | E11: Is very tall. → He is very tall. | F11: Англи өгүүлбэрт өгүүлэгдэхүүн заавал байна.
A12: 1 | B12: GR-003 | C12: 10 | D12: Watch out | E12: i am a student. → I am a student. | F12: I үргэлж том үсгээр бичигдэнэ.
A13: 1 | B13: GR-003 | C13: 11 | D13: Remember | E13: тэр → he (a man) · she (a woman) · it (a thing) | F13: тэр → he (эрэгтэй) · she (эмэгтэй) · it (юм)
... A130: 10 | B130: GR-016 | C130: 12 | D130: Remember | E130: Mongolian: хайрцган дотор. English: in the box. | F130: Монголоор угтвар үг ард, англиар урд.

Sheet 03 Questions
A1: ID | B1: Lesson | C1: Code | D1: Block | E1: Round | F1: Type | G1: Instruction (MN) | H1: Instruction (EN) | I1: Question | J1: Options | K1: Answer | L1: Also accept | M1: Hint (MN) | N1: Image needed | O1: Translation (MN) | P1: Skill tag | Q1: Feedback if wrong (MN) | R1: Feedback if wrong (EN) | S1: Watch again: slide
A2: L01-P01 | B2: 1 | C2: GR-003 | D2: Practice | E2: 1 Recognise | F2: MCQ | G2: Зөв хариултыг сонго. | H2: Choose the right answer. | I2: Bat is my friend. ___ is 12. | J2: He|She|It | K2: He | O2: Бат миний найз. Тэр 12 настай. | P2: L1_HESHE | Q2: Эрэгтэй бол he, эмэгтэй бол she. Монголын "тэр" англиар гурван өөр үг. | R2: A man or a boy is he; a woman or a girl is she. | S2: 6
A3: L01-P02 | B3: 1 | C3: GR-003 | D3: Practice | E3: 1 Recognise | F3: MCQ | G3: Зөв хариултыг сонго. | H3: Choose the right answer. | I3: My mother is a doctor. ___ is kind. | J3: He|She|It | K3: She | O3: Ээж маань эмч. Тэр сайхан сэтгэлтэй. | P3: L1_HESHE | Q3: Эрэгтэй бол he, эмэгтэй бол she. Монголын "тэр" англиар гурван өөр үг. | R3: A man or a boy is he; a woman or a girl is she. | S3: 6
A4: L01-P03 | B4: 1 | C4: GR-003 | D4: Practice | E4: 1 Recognise | F4: MCQ | G4: Зөв хариултыг сонго. | H4: Choose the right answer. | I4: This is my phone. ___ is new. | J4: He|She|It | K4: It | O4: Энэ миний утас. Тэр шинэ. | P4: L1_IT | Q4: Юм, газар, амьтан бол it. | R4: A thing, a place or an animal is it. | S4: 6
A5: L01-P04 | B5: 1 | C5: GR-003 | D5: Practice | E5: 1 Recognise | F5: MCQ | G5: Зөв хариултыг сонго. | H5: Choose the right answer. | I5: Saraa and I are friends. ___ are in the same class. | J5: We|They|You | K5: We | O5: Сараа бид хоёр найзууд. Бид нэг ангийнх. | P5: L1_PLURAL | Q5: Олон хүн: өөрөө орсон бол we, ороогүй бол they. | R5: More than one person: we if you are one of them, they if you are not. | S5: 4
A6: L01-P05 | B6: 1 | C6: GR-003 | D6: Practice | E6: 1 Recognise | F6: MCQ | G6: Зөв хариултыг сонго. | H6: Choose the right answer. | I6: My grandparents are in Khovd. ___ are very kind. | J6: We|They|He | K6: They | O6: Өвөө эмээ маань Ховдод байдаг. Тэд их сайхан сэтгэлтэй. | P6: L1_PLURAL | Q6: Олон хүн: өөрөө орсон бол we, ороогүй бол they. | R6: More than one person: we if you are one of them, they if you are not. | S6: 4
A7: L01-P06 | B7: 1 | C7: GR-003 | D7: Practice | E7: 1 Recognise | F7: MCQ | G7: Зөв хариултыг сонго. | H7: Choose the right answer. | I7: Чи, та, та нар: англиар аль үг вэ? | J7: you|he|they | K7: you | P7: L1_YOU | Q7: Чи, та, та нар бүгд англиар you. | R7: чи, та and та нар are all you in English. | S7: 5
A8: L01-P07 | B8: 1 | C8: GR-003 | D8: Practice | E8: 2 Build | F8: MATCH | G8: Хосыг нь холбо. | H8: Match the pairs. | J8: I=би|we=бид|they=тэд|you=чи, та | K8: I=би|we=бид|they=тэд|you=чи, та | P8: L1_SYSTEM | Q8: Долоон төлөөний үг: I, you, he, she, it, we, they. | R8: The seven pronouns: I, you, he, she, it, we, they. | S8: 4
A9: L01-P08 | B9: 1 | C9: GR-003 | D9: Practice | E9: 2 Build | F9: SORT | G9: Үгсийг зөв бүлэгт хуваа. | H9: Sort the words into the right group. | I9: he, she or it? | J9: my father|my sister|the school|my brother|my mother|my cat | K9: he=my father,my brother|she=my sister,my mother|it=the school,my cat | P9: L1_HESHE | Q9: Эрэгтэй бол he, эмэгтэй бол she. Монголын "тэр" англиар гурван өөр үг. | R9: A man or a boy is he; a woman or a girl is she. | S9: 6
A10: L01-P09 | B10: 1 | C10: GR-003 | D10: Practice | E10: 2 Build | F10: ORDER | G10: Үгсийг зөв дарааллаар байрлуул. | H10: Put the words in the right order. | J10: is|She|a|teacher | K10: She is a teacher. | O10: Тэр багш. | P10: L1_HESHE | Q10: Эрэгтэй бол he, эмэгтэй бол she. Монголын "тэр" англиар гурван өөр үг. | R10: A man or a boy is he; a woman or a girl is she. | S10: 6
A11: L01-P10 | B11: 1 | C11: GR-003 | D11: Practice | E11: 2 Build | F11: ORDER | G11: Үгсийг зөв дарааллаар байрлуул. | H11: Put the words in the right order. | J11: am|I|tired|today | K11: I am tired today. | L11: Today I am tired. | O11: Би өнөөдөр ядарч байна. | P11: L1_CAPI | Q11: I үргэлж том үсгээр бичигдэнэ. | R11: I is always a capital letter. | S11: 7
A12: L01-P11 | B12: 1 | C12: GR-003 | D12: Practice | E12: 2 Build | F12: GAP | G12: Үгийг сонгоод хоосон зайг нөх. | H12: Tap a word to fill each gap. | I12: My father is a driver. ___ is tall. My sister is 10. ___ is short. | J12: He|She|It | K12: He|She | O12: Аав маань жолооч. Тэр өндөр. Дүү маань 10 настай. Тэр намхан. | P12: L1_HESHE | Q12: Эрэгтэй бол he, эмэгтэй бол she. Монголын "тэр" англиар гурван өөр үг. | R12: A man or a boy is he; a woman or a girl is she. | S12: 6
A13: L01-P12 | B13: 1 | C13: GR-003 | D13: Practice | E13: 2 Build | F13: GAP | G13: Үгийг сонгоод хоосон зайг нөх. | H13: Tap a word to fill each gap. | I13: ___ is cold today. | J13: It|He|She | K13: It | O13: Өнөөдөр хүйтэн байна. | P13: L1_SUBJ | Q13: Англи өгүүлбэрт өгүүлэгдэхүүн заавал байна: It is cold. | R13: Every English sentence needs a subject, even It is cold. | S13: 7
A14: L01-P13 | B14: 1 | C14: GR-003 | D14: Practice | E14: 2 Build | F14: GAP | G14: Үгийг сонгоод хоосон зайг нөх. | H14: Tap a word to fill each gap. | I14: Anu and Bolor are my friends. ___ are 13. | J14: We|They|You | K14: They | O14: Ану, Болор хоёр миний найзууд. Тэд 13 настай. | P14: L1_PLURAL | Q14: Олон хүн: өөрөө орсон бол we, ороогүй бол they. | R14: More than one person: we if you are one of them, they if you are not. | S14: 4
A15: L01-P14 | B15: 1 | C15: GR-003 | D15: Practice | E15: 2 Build | F15: MCQ | G15: Зөв хариултыг сонго. | H15: Choose the right answer. | I15: Чи багштайгаа ярьж байна. Аль үгийг хэрэглэх вэ? | J15: you|he|she | K15: you | P15: L1_YOU | Q15: Чи, та, та нар бүгд англиар you. | R15: чи, та and та нар are all you in English. | S15: 5
A16: L01-P15 | B16: 1 | C16: GR-003 | D16: Practice | E16: 3 Fix it | F16: FIX | G16: Алдаатай үгийг олоод зас. | H16: Find the wrong word and fix it. | I16: My mother is a teacher. He is kind. | J16: She|It|They | K16: He → She | O16: Ээж маань багш. Тэр сайхан сэтгэлтэй. | P16: L1_HESHE | Q16: Эрэгтэй бол he, эмэгтэй бол she. Монголын "тэр" англиар гурван өөр үг. | R16: A man or a boy is he; a woman or a girl is she. | S16: 6
A17: L01-P16 | B17: 1 | C17: GR-003 | D17: Practice | E17: 3 Fix it | F17: FIX | G17: Алдаатай үгийг олоод зас. | H17: Find the wrong word and fix it. | I17: Bat is my brother. She is 15. | J17: He|It|They | K17: She → He | O17: Бат миний ах. Тэр 15 настай. | P17: L1_HESHE | Q17: Эрэгтэй бол he, эмэгтэй бол she. Монголын "тэр" англиар гурван өөр үг. | R17: A man or a boy is he; a woman or a girl is she. | S17: 6
A18: L01-P17 | B18: 1 | C18: GR-003 | D18: Practice | E18: 3 Fix it | F18: FIX | G18: Алдаатай үгийг олоод зас. | H18: Find the wrong word and fix it. | I18: i am a student. | J18: I|Me|My | K18: i → I | O18: Би сурагч. | P18: L1_CAPI | Q18: I үргэлж том үсгээр бичигдэнэ. | R18: I is always a capital letter. | S18: 7
A19: L01-P18 | B19: 1 | C19: GR-003 | D19: Practice | E19: 3 Fix it | F19: FIX | G19: Алдаатай үгийг олоод зас. | H19: Find the wrong word and fix it. | I19: My phone is new. He is black. | J19: It|She|They | K19: He → It | O19: Миний утас шинэ. Тэр хар өнгөтэй. | P19: L1_IT | Q19: Юм, газар, амьтан бол it. | R19: A thing, a place or an animal is it. | S19: 6
A20: L01-C01 | B20: 1 | C20: GR-003 | D20: Check bank | F20: MCQ | G20: Зөв хариултыг сонго. | H20: Choose the right answer. | I20: Saraa is a student. ___ is 14. | J20: He|She|It | K20: She | O20: Сараа сурагч. Тэр 14 настай. | P20: L1_HESHE | Q20: Эрэгтэй бол he, эмэгтэй бол she. Монголын "тэр" англиар гурван өөр үг. | R20: A man or a boy is he; a woman or a girl is she. | S20: 6
A21: L01-C02 | B21: 1 | C21: GR-003 | D21: Check bank | F21: MCQ | G21: Зөв хариултыг сонго. | H21: Choose the right answer. | I21: My brother is a doctor. ___ is 30. | J21: He|She|It | K21: He | O21: Ах маань эмч. Тэр 30 настай. | P21: L1_HESHE | Q21: Эрэгтэй бол he, эмэгтэй бол she. Монголын "тэр" англиар гурван өөр үг. | R21: A man or a boy is he; a woman or a girl is she. | S21: 6
A22: L01-C03 | B22: 1 | C22: GR-003 | D22: Check bank | F22: MCQ | G22: Зөв хариултыг сонго. | H22: Choose the right answer. | I22: This is our school. ___ is big. | J22: He|She|It | K22: It | O22: Энэ манай сургууль. Тэр том. | P22: L1_IT | Q22: Юм, газар, амьтан бол it. | R22: A thing, a place or an animal is it. | S22: 6
A23: L01-C04 | B23: 1 | C23: GR-003 | D23: Check bank | F23: MCQ | G23: Зөв хариултыг сонго. | H23: Choose the right answer. | I23: Bat and I are students. ___ are in the same school. | J23: We|They|You | K23: We | O23: Бат бид хоёр сурагчид. Бид нэг сургуульд сурдаг. | P23: L1_PLURAL | Q23: Олон хүн: өөрөө орсон бол we, ороогүй бол they. | R23: More than one person: we if you are one of them, they if you are not. | S23: 4
A24: L01-C05 | B24: 1 | C24: GR-003 | D24: Check bank | F24: MCQ | G24: Зөв хариултыг сонго. | H24: Choose the right answer. | I24: My parents are teachers. ___ are kind. | J24: We|They|It | K24: They | O24: Аав ээж маань багш нар. Тэд сайхан сэтгэлтэй. | P24: L1_PLURAL | Q24: Олон хүн: өөрөө орсон бол we, ороогүй бол they. | R24: More than one person: we if you are one of them, they if you are not. | S24: 4
A25: L01-C06 | B25: 1 | C25: GR-003 | D25: Check bank | F25: MCQ | G25: Зөв хариултыг сонго. | H25: Choose the right answer. | I25: My teacher is Saraa. ___ is very kind. | J25: He|She|It | K25: She | O25: Миний багш Сараа. Тэр их сайхан сэтгэлтэй. | P25: L1_HESHE | Q25: Эрэгтэй бол he, эмэгтэй бол she. Монголын "тэр" англиар гурван өөр үг. | R25: A man or a boy is he; a woman or a girl is she. | S25: 6
A26: L01-C07 | B26: 1 | C26: GR-003 | D26: Check bank | F26: MCQ | G26: Зөв хариултыг сонго. | H26: Choose the right answer. | I26: Where is my bag? ___ is on the table. | J26: He|She|It | K26: It | O26: Миний цүнх хаана байна? Ширээн дээр байна. | P26: L1_IT | Q26: Юм, газар, амьтан бол it. | R26: A thing, a place or an animal is it. | S26: 6
A27: L01-C08 | B27: 1 | C27: GR-003 | D27: Check bank | F27: MCQ | G27: Зөв хариултыг сонго. | H27: Choose the right answer. | I27: Tuvshin is my friend. ___ is from Khovd. | J27: He|She|It | K27: He | O27: Түвшин миний найз. Тэр Ховдоос ирсэн. | P27: L1_HESHE | Q27: Эрэгтэй бол he, эмэгтэй бол she. Монголын "тэр" англиар гурван өөр үг. | R27: A man or a boy is he; a woman or a girl is she. | S27: 6
A28: L01-C09 | B28: 1 | C28: GR-003 | D28: Check bank | F28: MCQ | G28: Зөв хариултыг сонго. | H28: Choose the right answer. | I28: My sister and my brother are at home. ___ are happy. | J28: We|They|He | K28: They | O28: Эгч, ах хоёр маань гэртээ байна. Тэд баяртай байна. | P28: L1_PLURAL | Q28: Олон хүн: өөрөө орсон бол we, ороогүй бол they. | R28: More than one person: we if you are one of them, they if you are not. | S28: 4
A29: L01-C10 | B29: 1 | C29: GR-003 | D29: Check bank | F29: FIX | G29: Алдаатай үгийг олоод зас. | H29: Find the wrong word and fix it. | I29: My father is a driver. She is tall. | J29: He|It|They | K29: She → He | O29: Аав маань жолооч. Тэр өндөр. | P29: L1_HESHE | Q29: Эрэгтэй бол he, эмэгтэй бол she. Монголын "тэр" англиар гурван өөр үг. | R29: A man or a boy is he; a woman or a girl is she. | S29: 6
A30: L01-C11 | B30: 1 | C30: GR-003 | D30: Check bank | F30: FIX | G30: Алдаатай үгийг олоод зас. | H30: Find the wrong word and fix it. | I30: Saraa and Anu are friends. We are 12. | J30: They|You|He | K30: We → They | O30: Сараа, Ану хоёр найзууд. Тэд 12 настай. | P30: L1_PLURAL | Q30: Олон хүн: өөрөө орсон бол we, ороогүй бол they. | R30: More than one person: we if you are one of them, they if you are not. | S30: 4
A31: L01-C12 | B31: 1 | C31: GR-003 | D31: Check bank | F31: FIX | G31: Алдаатай үгийг олоод зас. | H31: Find the wrong word and fix it. | I31: Today i am happy. | J31: I|Me|My | K31: i → I | O31: Өнөөдөр би баяртай байна. | P31: L1_CAPI | Q31: I үргэлж том үсгээр бичигдэнэ. | R31: I is always a capital letter. | S31: 7
A32: L01-C13 | B32: 1 | C32: GR-003 | D32: Check bank | F32: GAP | G32: Үгийг сонгоод хоосон зайг нөх. | H32: Tap a word to fill each gap. | I32: ___ is hot today. | J32: It|He|She | K32: It | O32: Өнөөдөр халуун байна. | P32: L1_SUBJ | Q32: Англи өгүүлбэрт өгүүлэгдэхүүн заавал байна: It is cold. | R32: Every English sentence needs a subject, even It is cold. | S32: 7
A33: L01-C14 | B33: 1 | C33: GR-003 | D33: Check bank | F33: CHOOSE | G33: Зөв өгүүлбэрийг сонго. | H33: Choose the correct sentence. | J33: She is my mother.|He is my mother.|It is my mother. | K33: She is my mother. | O33: Тэр миний ээж. | P33: L1_HESHE | Q33: Эрэгтэй бол he, эмэгтэй бол she. Монголын "тэр" англиар гурван өөр үг. | R33: A man or a boy is he; a woman or a girl is she. | S33: 6
A34: L01-C15 | B34: 1 | C34: GR-003 | D34: Check bank | F34: CHOOSE | G34: Зөв өгүүлбэрийг сонго. | H34: Choose the correct sentence. | J34: I am 12.|Am 12.|i am 12. | K34: I am 12. | O34: Би 12 настай. | P34: L1_SUBJ | Q34: Англи өгүүлбэрт өгүүлэгдэхүүн заавал байна: It is cold. | R34: Every English sentence needs a subject, even It is cold. | S34: 7
A35: L01-C16 | B35: 1 | C35: GR-003 | D35: Check bank | F35: MCQ | G35: Зөв хариултыг сонго. | H35: Choose the right answer. | I35: Юм, амьтныг аль үгээр хэлэх вэ? | J35: he|she|it | K35: it | P35: L1_IT | Q35: Юм, газар, амьтан бол it. | R35: A thing, a place or an animal is it. | S35: 6
A36: L01-C17 | B36: 1 | C36: GR-003 | D36: Check bank | F36: GAP | G36: Үгийг сонгоод хоосон зайг нөх. | H36: Tap a word to fill each gap. | I36: My friends and I are at school. ___ are in the classroom. | J36: We|They|You | K36: We | O36: Найзууд бид хоёр сургууль дээр байна. Бид ангидаа байна. | P36: L1_PLURAL | Q36: Олон хүн: өөрөө орсон бол we, ороогүй бол they. | R36: More than one person: we if you are one of them, they if you are not. | S36: 4
A37: L01-C18 | B37: 1 | C37: GR-003 | D37: Check bank | F37: MCQ | G37: Зөв хариултыг сонго. | H37: Choose the right answer. | I37: Чи, та, та нар: англиар хэдэн үгтэй вэ? | J37: one: you|two: you, your|three: you, he, they | K37: one: you | P37: L1_YOU | Q37: Чи, та, та нар бүгд англиар you. | R37: чи, та and та нар are all you in English. | S37: 5
A38: L01-C19 | B38: 1 | C38: GR-003 | D38: Check bank | F38: ORDER | G38: Үгсийг зөв дарааллаар байрлуул. | H38: Put the words in the right order. | J38: are|They|my|parents | K38: They are my parents. | O38: Тэд миний аав ээж. | P38: L1_PLURAL | Q38: Олон хүн: өөрөө орсон бол we, ороогүй бол they. | R38: More than one person: we if you are one of them, they if you are not. | S38: 4
A39: L01-C20 | B39: 1 | C39: GR-003 | D39: Check bank | F39: ORDER | G39: Үгсийг зөв дарааллаар байрлуул. | H39: Put the words in the right order. | J39: is|It|my|cat | K39: It is my cat. | O39: Энэ миний муур. | P39: L1_IT | Q39: Юм, газар, амьтан бол it. | R39: A thing, a place or an animal is it. | S39: 6
A40: L02-P01 | B40: 2 | C40: GR-004 | D40: Practice | E40: 1 Recognise | F40: MCQ | G40: Зөв хариултыг сонго. | H40: Choose the right answer. | I40: I ___ a student. | J40: am|is|are | K40: am | O40: Би сурагч. | P40: L2_AM | Q40: I-тэй үргэлж am хэрэглэнэ. | R40: I always takes am. | S40: 4
...

Sheet 04 Skill tags
A1: Skill tag | B1: Lesson | C1: Skill | D1: Explanation (EN) | E1: Feedback (MN) | F1: Teaching slide | G1: Questions
A2: L1_HESHE | B2: 1 | C2: he or she | D2: A man or a boy is he; a woman or a girl is she. | E2: Эрэгтэй бол he, эмэгтэй бол she. Монголын "тэр" англиар гурван өөр үг. | F2: 6 | G2: =COUNTIF('03 Questions'!$P$2:$P$421,A2) -> 16
A3: L1_IT | B3: 1 | C3: it | D3: A thing, a place or an animal is it. | E3: Юм, газар, амьтан бол it. | F3: 6 | G3: =COUNTIF('03 Questions'!$P$2:$P$421,A3) -> 6
A4: L1_PLURAL | B4: 1 | C4: we or they | D4: More than one person: we if you are one of them, they if you are not. | E4: Олон хүн: өөрөө орсон бол we, ороогүй бол they. | F4: 4 | G4: =COUNTIF('03 Questions'!$P$2:$P$421,A4) -> 10
A5: L1_YOU | B5: 1 | C5: you | D5: чи, та and та нар are all you in English. | E5: Чи, та, та нар бүгд англиар you. | F5: 5 | G5: =COUNTIF('03 Questions'!$P$2:$P$421,A5) -> 3
A6: L1_SYSTEM | B6: 1 | C6: the seven pronouns | D6: The seven pronouns: I, you, he, she, it, we, they. | E6: Долоон төлөөний үг: I, you, he, she, it, we, they. | F6: 4 | G6: =COUNTIF('03 Questions'!$P$2:$P$421,A6) -> 1
A7: L1_CAPI | B7: 1 | C7: capital I | D7: I is always a capital letter. | E7: I үргэлж том үсгээр бичигдэнэ. | F7: 7 | G7: =COUNTIF('03 Questions'!$P$2:$P$421,A7) -> 3
A8: L1_SUBJ | B8: 1 | C8: subject needed | D8: Every English sentence needs a subject, even It is cold. | E8: Англи өгүүлбэрт өгүүлэгдэхүүн заавал байна: It is cold. | F8: 7 | G8: =COUNTIF('03 Questions'!$P$2:$P$421,A8) -> 4
A9: L2_AM | B9: 2 | C9: I am | D9: I always takes am. | E9: I-тэй үргэлж am хэрэглэнэ. | F9: 4 | G9: =COUNTIF('03 Questions'!$P$2:$P$421,A9) -> 5
A10: L2_IS | B10: 2 | C10: is | D10: He, she, it and one person or thing take is. | E10: He, she, it болон нэг хүн, юм бол is. | F10: 5 | G10: =COUNTIF('03 Questions'!$P$2:$P$421,A10) -> 14
A11: L2_ARE | B11: 2 | C11: are | D11: You, we, they and more than one take are. | E11: You, we, they болон нэгээс олон бол are. | F11: 5 | G11: =COUNTIF('03 Questions'!$P$2:$P$421,A11) -> 12
A12: L2_VERB | B12: 2 | C12: verb needed | D12: Mongolian says Би сурагч with no verb; English needs one: I am a student. | E12: Монголоор "Би сурагч" гэхэд үйл үг хэрэггүй, англиар заавал хэрэгтэй: I am a student. | F12: 8 | G12: =COUNTIF('03 Questions'!$P$2:$P$421,A12) -> 4
A13: L2_SHORT | B13: 2 | C13: short forms | D13: The apostrophe shows a missing letter: I'm = I am. | E13: Апостроф хасагдсан үсгийг заана: I'm = I am. | F13: 7 | G13: =COUNTIF('03 Questions'!$P$2:$P$421,A13) -> 4
... A65: L10_ORDER | B65: 10 | C65: word order | D65: In English the preposition comes before the noun, with the: in the box. | E65: Англиар угтвар үг нэр үгийн өмнө, the-тэй: in the box. | F65: 7 | G65: =COUNTIF('03 Questions'!$P$2:$P$421,A65) -> 5

Sheet 05 Question types
A1: Type | B1: Name (MN) | C1: What the student does | D1: Question column | E1: Options column | F1: Answer column | G1: Marking
A2: MCQ | B2: Сонголттой асуулт | C2: Reads a sentence with a gap (or a short Mongolian question) and taps one of 2 to 4 buttons. | D2: Sentence with ___ for the gap, or a question in Mongolian. | E2: Choices separated by | | F2: The correct choice, written out. | G2: Right or wrong.
A3: CHOOSE | B3: Зөв өгүүлбэр сонгох | C3: Sees 3 whole sentences and taps the correct one. | D3: Usually empty. Sometimes a short lead-in such as a question being answered. | E3: Three sentences separated by | | F3: The correct sentence. | G3: Right or wrong.
A4: GAP | B4: Хоосон зай нөхөх | C4: Sees a sentence with one or more gaps and a word bank; taps a word into each gap in order. | D4: Sentence with one ___ per gap. | E4: Word bank separated by |. Words may be used more than once. | F4: One word per gap, in order, separated by | | G4: Right only if every gap is right. Show which gap was wrong.
A5: ORDER | B5: Дараалал | C5: Taps word tiles to build the sentence. | D5: Empty. | E5: Tiles separated by | (already shuffled; shuffle again on screen). | F5: The full sentence. Punctuation is added automatically, not a tile, except ? when shown as a tile. | G5: Right if it matches Answer or Also accept.
A6: MATCH | B6: Холбох | C6: Taps an item on the left, then its partner on the right. | D6: Empty. | E6: Pairs written left=right, separated by |. Show the right side shuffled. | F6: Same as Options. | G6: Each pair marked; the question is right when every pair is right.
A7: SORT | B7: Бүлэглэх | C7: Taps or drags each word into one of two groups. | D7: The two-group question, e.g. a or an? | E7: The words to sort, separated by | | F7: group=word,word|group=word,word. The two group names are the box labels. | G7: Each word marked; the question is right when every word is in the right group.
A8: FIX | B8: Алдаа засах | C8: Taps the one wrong word in the sentence, then taps the correction from 3 choices. | D8: Sentence containing exactly one wrong word (or phrase). | E8: Three corrections separated by | | F8: wrong → right | G8: Right only if both the wrong word and the correction are right. If they tap a correct word, say so and let them try again.

Sheet 06 Interface text
A1: Key | B1: English | C1: Монгол | D1: Where it appears
A2: block.notes | B2: Notes | C2: Тэмдэглэл | D2: Tab or section title under the video
A3: block.practice | B3: Practice | C3: Дасгал | D3: Tab or section title
A4: block.check | B4: Check | C4: Шалгалт | D4: Tab or section title
A5: round.1 | B5: Round 1: Recognise | C5: 1-р шат: Таних | D5: Practice, round heading
A6: round.2 | B6: Round 2: Build | C6: 2-р шат: Бүтээх | D6: Practice, round heading
A7: round.3 | B7: Round 3: Fix it | C7: 3-р шат: Засах | D7: Practice, round heading
A8: unit.title | B8: Unit test | C8: Бүлгийн шалгалт | D8: Unit test page title
A9: review.title | B9: Review your mistakes | C9: Алдаагаа давт | D9: Dashboard card and page title
A10: review.intro | B10: These are questions you got wrong before. Let's fix them. | C10: Эдгээр нь өмнө нь алдсан асуултууд. Хамтдаа засъя. | D10: Top of a review session
A11: review.empty | B11: Nothing to review today. Well done! | C11: Өнөөдөр давтах зүйл алга. Сайн байна! | D11: Review page when the list is empty
A12: btn.check | B12: Check | C12: Шалгах | D12: Button under a question
... A30: lesson.complete | B30: Lesson complete | C30: Хичээл дууссан | D30: Badge on the lesson card
